Workbook

Sheet Synthèse
A1: PRÉVISIONNEL — LOCATION DE MINI-PELLE & TRAVAUX ANNEXES
A2: Société en création — 2 associés à 50/50 — capital 1 000 €. Document de travail à destination de l'expert-comptable.
A4: Démarrage | B4: Montant
A5: Total des besoins de démarrage | B5: =Financement!$B$11 -> 67200
A6: Apports des associés (capital + comptes courants) | B6: =Financement!$E$4+Financement!$E$5 -> 11000
A7: Emprunt bancaire à solliciter | B7: =Financement!$E$6 -> 56200
A8: Mensualité d'emprunt | B8: =Financement!$B$18 -> 1040.0886
A10: Indicateurs (€ HT) | B10: Année 1 | C10: Année 2 | D10: Année 3
A11: CA location mini-pelle | B11: ='Compte de résultat'!$B$5 -> 65510 | C11: ='Compte de résultat'!$C$5 -> 75336.5 | D11: ='Compte de résultat'!$D$5 -> 82870.15
A12: CA travaux annexes | B12: ='Compte de résultat'!$B$6 -> 65000 | C12: ='Compte de résultat'!$C$6 -> 74750 | D12: ='Compte de résultat'!$D$6 -> 82225
A13: Chiffre d'affaires total | B13: ='Compte de résultat'!$B$7 -> 130510 | C13: ='Compte de résultat'!$C$7 -> 150086.5 | D13: ='Compte de résultat'!$D$7 -> 165095.15
A14: EBE | B14: ='Compte de résultat'!$B$22 -> 59350 | C14: ='Compte de résultat'!$C$22 -> 49560.5 | D14: ='Compte de résultat'!$D$22 -> 43628.55
A15: Résultat net | B15: ='Compte de résultat'!$B$30 -> 37190.035 | C15: ='Compte de résultat'!$C$30 -> 29811.484 | D15: ='Compte de résultat'!$D$30 -> 25160.924
A16: Rémunération nette des 2 associés | B16: ='Compte de résultat'!$B$20 -> 18000 | C16: ='Compte de résultat'!$C$20 -> 36000 | D16: ='Compte de résultat'!$D$20 -> 48000
A17: CAF | B17: ='Compte de résultat'!$B$34 -> 49956.702 | C17: ='Compte de résultat'!$C$34 -> 42578.15 | D17: ='Compte de résultat'!$D$34 -> 37927.59
A18: Trésorerie dégagée après remboursement d'emprunt | B18: ='Compte de résultat'!$B$36 -> 39638.925 | C18: ='Compte de résultat'!$C$36 -> 31818.587 | D18: ='Compte de résultat'!$D$36 -> 26707.324
A20: Points clés année 1 | B20: Valeur
A21: Jours de location / mois en moyenne (avec + sans opérateur) | B21: ='Activité A1'!$N$7/12 -> 12.083333
A22: Taux d'utilisation moyen de la mini-pelle | B22: ='Activité A1'!$N$8 -> 0.57539683
A23: Seuil de rentabilité (CA HT) | B23: ='Rentabilité & seuil'!$B$31 -> 75431.636
A24: Trésorerie minimale atteinte en année 1 | B24: ='Trésorerie A1'!$N$34 -> 4199.7114
A25: Trésorerie en fin d'année 1 | B25: ='Trésorerie A1'!$N$26 -> 49175.203

Sheet Lisez-moi
A1: NOTE DE PRÉSENTATION POUR L'EXPERT-COMPTABLE
A3: 1. Le projet
A4: Création d'une société de location de mini-pelle 2,5 t, avec ou sans opérateur, et de travaux sur devis : terrassement, évacuation des déchets, maçonnerie après terrassement, élagage et entretien d'espaces verts. Clients : particuliers et entreprises (projets extérieurs, création d'accès pour engins).
A5: Secteur : Mâcon et alentours. Veille de marché : 8 concurrents directs importants et une dizaine de structures intermédiaires peu équipées. La location avec opérateur pour les particuliers est peu proposée (ni par les grandes enseignes, ni par le TP) : c'est le positionnement différenciant.
A6: 2 associés à parts égales (50/50), capital social de 1 000 €. Répartition des rôles : un associé gère la communication, l'administratif, les devis, la facturation et le suivi clients ; l'autre (Alexandre) gère le terrain : visites préalables et réalisation des travaux.
A7: Expérience : l'associé chargé de l'administratif a créé et dirige depuis 2022 l'agence Corberon Location (location de nacelles, Replonges) : 1,18 M€ de CA et 264 k€ de bénéfice en 2024, ≈ 1 M€ de CA prévu en 2026, 6 personnes. Les deux associés utilisent déjà la mini-pelle dans leur activité.
A8: Investissements : mini-pelle 2,5 t (25–30 k€), remorque plateau d'occasion (~8 k€), petit camion benne d'occasion (15–25 k€), matériel et équipements divers, trésorerie de départ. Budget total envisagé : 50 000 à 70 000 €.
A9: Tarifs : 250–350 € HT/jour sans opérateur ; 650–950 € HT/jour (7 h) avec opérateur, hors déplacement. Travaux annexes sur devis.
A10: Objectif année 1 : au moins 65 000 € HT de CA sur la location seule, et environ le double (≈ 130 000 € HT) sur l'ensemble de la société.
A11: Estimation des associés : il faut au minimum 12 jours de location sans opérateur par mois, ou 6 à 8 jours avec opérateur, pour rentabiliser l'achat (à comparer avec la feuille « Rentabilité & seuil »).
A13: 2. Organisation du fichier
A14: Synthèse : chiffres clés et graphiques. • Hypothèses : TOUTES les données modifiables. • Financement : plan de financement + tableau d'emprunt.
... A34: Montants indicatifs basés sur des estimations de marché : à affiner avec les devis réels (matériel, assurances, banque) et la lettre de mission de la comptable. Pas de salarié prévu. Stocks et délais fournisseurs non modélisés (paiement comptant). Les taux fiscaux et sociaux sont à vérifier à la date de création.

Sheet Hypothèses
A1: HYPOTHÈSES DU PRÉVISIONNEL — tous montants en € HT
A2: Cellules en bleu = données saisies (modifiables). Surlignées en jaune = hypothèses clés à valider / compléter. Noir = calculs. Vert = liens vers une autre feuille.
A4: Général
A5: Date de démarrage de l'activité (1er mois) | B5: 46388 | F5: Hypothèse : démarrage au 1er janvier 2027, à ajuster selon la date d'immatriculation.
A6: Jours ouvrés par mois (capacité d'une machine) | B6: 21 | C6: jours | F6: Sert au calcul du taux d'utilisation de la mini-pelle.
A8: Investissements de départ (HT)
A9: Mini-pelle 2,5 t | B9: 27500 | C9: € HT | F9: Donnée fournie : 25 000 à 30 000 € → milieu de fourchette retenu.
A10: Remorque plateau d'occasion | B10: 8000 | C10: € HT | F10: Donnée fournie : environ 8 000 € d'occasion.
A11: Petit camion benne d'occasion | B11: 20000 | C11: € HT | F11: Donnée fournie : entre 15 000 et 25 000 € → milieu de fourchette retenu.
A12: Matériel & équipements divers (godets, BRH, outillage, EPI...) | B12: 5000 | C12: € HT | F12: Estimation : « matériel et équipement en tous genres ».
A13: Frais d'établissement (statuts, annonce légale, greffe, formalités) | B13: 1200 | C13: € | F13: Estimation. Comptabilisés en charges la 1re année.
A14: Trésorerie de départ (fonds de roulement) | B14: 5000 | C14: € | F14: Donnée fournie : « un peu de trésorerie de départ ». Montant à ajuster.
A16: Durées d'amortissement (linéaire)
A17: Mini-pelle d'occasion | B17: 5 | C17: ans | F17: Usage courant pour un engin d'occasion (à valider avec la comptable).
A18: Remorque plateau | B18: 5 | C18: ans
A19: Camion benne d'occasion | B19: 5 | C19: ans
A20: Matériel & équipements | B20: 3 | C20: ans | F20: Le petit matériel < 500 € HT par unité peut être passé directement en charges.
A22: Financement
A23: Capital social | B23: 1000 | C23: € | F23: Donnée fournie : 1 000 €, réparti 50/50 (500 € chacun).
A24: Apports en compte courant d'associés | B24: 10000 | C24: € | F24: Hypothèse : 5 000 € par associé, remboursables quand la trésorerie le permet. Mettre 0 si aucun apport.
A25: Taux de l'emprunt bancaire (annuel) | B25: 0.042 | F25: Hypothèse : taux professionnel indicatif 2026 pour un prêt matériel sur 5 ans. À remplacer par l'offre de la banque.
A26: Durée de l'emprunt | B26: 60 | C26: mois | F26: Hypothèse : 5 ans, aligné sur la durée d'amortissement du matériel.
A27: Frais de dossier bancaire + garantie | B27: 500 | C27: € | F27: Estimation.
A28: Montant de l'emprunt nécessaire (calculé) | B28: =Financement!$E$6 -> 56200 | F28: Total des besoins − capital − apports (feuille Financement).
A30: Chiffre d'affaires — prix de vente (HT)
A31: Location mini-pelle SANS opérateur (prix / jour) | B31: 280 | C31: € HT / jour | F31: Donnée fournie : 250 à 350 € HT/jour → bas de fourchette retenu par prudence. Déplacements facturés en plus (non comptés).
A32: Location mini-pelle AVEC opérateur (prix / journée de 7 h) | B32: 750 | C32: € HT / jour | F32: Donnée fournie : 650 à 950 € HT pour 7 h hors déplacement → bas de fourchette retenu par prudence.
A33: Travaux sur devis (terrassement, évacuation déchets, maçonnerie, élagage, espaces verts) — CA A1 | B33: 65000 | C33: € HT | F33: Objectif fourni : « envisager le double sur la société » → 65 k€ de location + 65 k€ de travaux = 130 k€.
A34: Croissance d'activité année 2 | B34: 0.15 | F34: Hypothèse.
A35: Croissance d'activité année 3 | B35: 0.1 | F35: Hypothèse.
A36: → Le nombre de jours loués par mois et la saisonnalité des travaux se saisissent dans la feuille « Activité A1 ».
A38: Charges variables
A39: Achats de matériaux / fournitures refacturés (en % du CA travaux) | B39: 0.3 | F39: Hypothèse : gravier, sable, béton, tuyaux, mise en décharge…
A40: Carburant (GNR) par jour de location AVEC opérateur | B40: 30 | C40: € HT / jour | F40: Hypothèse : ~3 L/h × 7 h × ~1,45 € HT/L. En location sèche, le client fait le plein.
A41: Usure / entretien variable par jour de location | B41: 10 | C41: € HT / jour | F41: Hypothèse : chenilles, godets, graissage, flexibles, provision au jour loué.
A42: Carburant & usure camion/engins sur travaux (en % du CA travaux) | B42: 0.06 | F42: Hypothèse.
A44: Rémunération des associés
A45: Nombre d'associés rémunérés | B45: 2 | F45: Donnée fournie : 2 associés à 50/50.
B46: Année 1 | C46: Année 2 | D46: Année 3
A47: Rémunération NETTE mensuelle par associé | B47: 1000 | C47: 1500 | D47: 2000 | F47: Hypothèse : vous ne vous verserez pas forcément de salaire au début → 1 000 € net/mois en A1 à partir du mois indiqué ci-dessous. Mettre 0 pour tester sans rémunération.
...

Sheet Financement
A1: PLAN DE FINANCEMENT INITIAL & EMPRUNT
A3: Besoins (HT) | B3: Montant | D3: Ressources | E3: Montant | G3: Tableau d'amortissement mensuel
A4: Mini-pelle d'occasion | B4: =Hypothèses!$B$9 -> 27500 | D4: Capital social | E4: =Hypothèses!$B$23 -> 1000 | G4: Année | H4: Mois n° | I4: Capital début | J4: Intérêts | K4: Capital remb. | L4: Capital fin
A5: Remorque plateau | B5: =Hypothèses!$B$10 -> 8000 | D5: Apports en compte courant d'associés | E5: =Hypothèses!$B$24 -> 10000 | G5: =INT((H5-1)/12)+1 -> 1 | H5: 1 | I5: =$B$15 -> 56200 | J5: =IF(H5>$B$17,0,I5*$B$16/12) -> 196.7 | K5: =IF(H5>$B$17,0,MIN(I5,$B$18-J5)) -> 843.3886 | L5: =I5-K5 -> 55356.611
A6: Camion benne | B6: =Hypothèses!$B$11 -> 20000 | D6: Emprunt bancaire (solde à financer) | E6: =MAX(0,B11-E4-E5) -> 56200 | G6: =INT((H6-1)/12)+1 -> 1 | H6: 2 | I6: =L5 -> 55356.611 | J6: =IF(H6>$B$17,0,I6*$B$16/12) -> 193.74814 | K6: =IF(H6>$B$17,0,MIN(I6,$B$18-J6)) -> 846.34046 | L6: =I6-K6 -> 54510.271
A7: Matériel & équipements | B7: =Hypothèses!$B$12 -> 5000 | G7: =INT((H7-1)/12)+1 -> 1 | H7: 3 | I7: =L6 -> 54510.271 | J7: =IF(H7>$B$17,0,I7*$B$16/12) -> 190.78595 | K7: =IF(H7>$B$17,0,MIN(I7,$B$18-J7)) -> 849.30266 | L7: =I7-K7 -> 53660.968
A8: Frais d'établissement | B8: =Hypothèses!$B$13 -> 1200 | G8: =INT((H8-1)/12)+1 -> 1 | H8: 4 | I8: =L7 -> 53660.968 | J8: =IF(H8>$B$17,0,I8*$B$16/12) -> 187.81339 | K8: =IF(H8>$B$17,0,MIN(I8,$B$18-J8)) -> 852.27522 | L8: =I8-K8 -> 52808.693
A9: Frais de dossier bancaire | B9: =Hypothèses!$B$27 -> 500 | G9: =INT((H9-1)/12)+1 -> 1 | H9: 5 | I9: =L8 -> 52808.693 | J9: =IF(H9>$B$17,0,I9*$B$16/12) -> 184.83043 | K9: =IF(H9>$B$17,0,MIN(I9,$B$18-J9)) -> 855.25818 | L9: =I9-K9 -> 51953.435
A10: Trésorerie de départ | B10: =Hypothèses!$B$14 -> 5000 | G10: =INT((H10-1)/12)+1 -> 1 | H10: 6 | I10: =L9 -> 51953.435 | J10: =IF(H10>$B$17,0,I10*$B$16/12) -> 181.83702 | K10: =IF(H10>$B$17,0,MIN(I10,$B$18-J10)) -> 858.25158 | L10: =I10-K10 -> 51095.183
A11: TOTAL DES BESOINS | B11: =SUM(B4:B10) -> 67200 | D11: TOTAL DES RESSOURCES | E11: =SUM(E4:E6) -> 67200 | G11: =INT((H11-1)/12)+1 -> 1 | H11: 7 | I11: =L10 -> 51095.183 | J11: =IF(H11>$B$17,0,I11*$B$16/12) -> 178.83314 | K11: =IF(H11>$B$17,0,MIN(I11,$B$18-J11)) -> 861.25546 | L11: =I11-K11 -> 50233.928
A12: TVA sur investissements à avancer (récupérée ensuite) | B12: =SUM(B4:B7)*Hypothèses!$B$52 -> 12100 | D12: Taux d'apport personnel | E12: =IF(E11=0,0,(E4+E5)/E11) -> 0.16369048 | G12: =INT((H12-1)/12)+1 -> 1 | H12: 8 | I12: =L11 -> 50233.928 | J12: =IF(H12>$B$17,0,I12*$B$16/12) -> 175.81875 | K12: =IF(H12>$B$17,0,MIN(I12,$B$18-J12)) -> 864.26986 | L12: =I12-K12 -> 49369.658
G13: =INT((H13-1)/12)+1 -> 1 | H13: 9 | I13: =L12 -> 49369.658 | J13: =IF(H13>$B$17,0,I13*$B$16/12) -> 172.7938 | K13: =IF(H13>$B$17,0,MIN(I13,$B$18-J13)) -> 867.2948 | L13: =I13-K13 -> 48502.363
A14: Caractéristiques de l'emprunt | G14: =INT((H14-1)/12)+1 -> 1 | H14: 10 | I14: =L13 -> 48502.363 | J14: =IF(H14>$B$17,0,I14*$B$16/12) -> 169.75827 | K14: =IF(H14>$B$17,0,MIN(I14,$B$18-J14)) -> 870.33033 | L14: =I14-K14 -> 47632.033
A15: Montant emprunté | B15: =Financement!$E$6 -> 56200 | G15: =INT((H15-1)/12)+1 -> 1 | H15: 11 | I15: =L14 -> 47632.033 | J15: =IF(H15>$B$17,0,I15*$B$16/12) -> 166.71211 | K15: =IF(H15>$B$17,0,MIN(I15,$B$18-J15)) -> 873.37649 | L15: =I15-K15 -> 46758.656
A16: Taux annuel | B16: =Hypothèses!$B$25 -> 0.042 | G16: =INT((H16-1)/12)+1 -> 1 | H16: 12 | I16: =L15 -> 46758.656 | J16: =IF(H16>$B$17,0,I16*$B$16/12) -> 163.6553 | K16: =IF(H16>$B$17,0,MIN(I16,$B$18-J16)) -> 876.43331 | L16: =I16-K16 -> 45882.223
A17: Durée (mois) | B17: =Hypothèses!$B$26 -> 60 | G17: =INT((H17-1)/12)+1 -> 2 | H17: 13 | I17: =L16 -> 45882.223 | J17: =IF(H17>$B$17,0,I17*$B$16/12) -> 160.58778 | K17: =IF(H17>$B$17,0,MIN(I17,$B$18-J17)) -> 879.50082 | L17: =I17-K17 -> 45002.722
A18: Mensualité (capital + intérêts) | B18: =IF(B15=0,0,PMT(B16/12,B17,-B15)) -> 1040.0886 | G18: =INT((H18-1)/12)+1 -> 2 | H18: 14 | I18: =L17 -> 45002.722 | J18: =IF(H18>$B$17,0,I18*$B$16/12) -> 157.50953 | K18: =IF(H18>$B$17,0,MIN(I18,$B$18-J18)) -> 882.57908 | L18: =I18-K18 -> 44120.143
A19: Coût total du crédit (intérêts) | B19: =B18*B17-B15 -> 6205.3163 | G19: =INT((H19-1)/12)+1 -> 2 | H19: 15 | I19: =L18 -> 44120.143 | J19: =IF(H19>$B$17,0,I19*$B$16/12) -> 154.4205 | K19: =IF(H19>$B$17,0,MIN(I19,$B$18-J19)) -> 885.6681 | L19: =I19-K19 -> 43234.475
G20: =INT((H20-1)/12)+1 -> 2 | H20: 16 | I20: =L19 -> 43234.475 | J20: =IF(H20>$B$17,0,I20*$B$16/12) -> 151.32066 | K20: =IF(H20>$B$17,0,MIN(I20,$B$18-J20)) -> 888.76794 | L20: =I20-K20 -> 42345.707
G21: =INT((H21-1)/12)+1 -> 2 | H21: 17 | I21: =L20 -> 42345.707 | J21: =IF(H21>$B$17,0,I21*$B$16/12) -> 148.20997 | K21: =IF(H21>$B$17,0,MIN(I21,$B$18-J21)) -> 891.87863 | L21: =I21-K21 -> 41453.828
A22: Synthèse annuelle de l'emprunt | G22: =INT((H22-1)/12)+1 -> 2 | H22: 18 | I22: =L21 -> 41453.828 | J22: =IF(H22>$B$17,0,I22*$B$16/12) -> 145.0884 | K22: =IF(H22>$B$17,0,MIN(I22,$B$18-J22)) -> 895.00021 | L22: =I22-K22 -> 40558.828
A23: Année | B23: Intérêts | C23: Capital remboursé | D23: Capital restant dû fin | G23: =INT((H23-1)/12)+1 -> 2 | H23: 19 | I23: =L22 -> 40558.828 | J23: =IF(H23>$B$17,0,I23*$B$16/12) -> 141.9559 | K23: =IF(H23>$B$17,0,MIN(I23,$B$18-J23)) -> 898.13271 | L23: =I23-K23 -> 39660.696
A24: Année 1 | B24: =SUMIFS($J:$J,$G:$G,1) -> 2163.2863 | C24: =SUMIFS($K:$K,$G:$G,1) -> 10317.777 | D24: =IFERROR(INDEX($L:$L,MATCH(1*12,$H:$H,0)),0) -> 45882.223 | G24: =INT((H24-1)/12)+1 -> 2 | H24: 20 | I24: =L23 -> 39660.696 | J24: =IF(H24>$B$17,0,I24*$B$16/12) -> 138.81243 | K24: =IF(H24>$B$17,0,MIN(I24,$B$18-J24)) -> 901.27617 | L24: =I24-K24 -> 38759.419
A25: Année 2 | B25: =SUMIFS($J:$J,$G:$G,2) -> 1721.4997 | C25: =SUMIFS($K:$K,$G:$G,2) -> 10759.564 | D25: =IFERROR(INDEX($L:$L,MATCH(2*12,$H:$H,0)),0) -> 35122.659 | G25: =INT((H25-1)/12)+1 -> 2 | H25: 21 | I25: =L24 -> 38759.419 | J25: =IF(H25>$B$17,0,I25*$B$16/12) -> 135.65797 | K25: =IF(H25>$B$17,0,MIN(I25,$B$18-J25)) -> 904.43064 | L25: =I25-K25 -> 37854.989
A26: Année 3 | B26: =SUMIFS($J:$J,$G:$G,3) -> 1260.7966 | C26: =SUMIFS($K:$K,$G:$G,3) -> 11220.267 | D26: =IFERROR(INDEX($L:$L,MATCH(3*12,$H:$H,0)),0) -> 23902.393 | G26: =INT((H26-1)/12)+1 -> 2 | H26: 22 | I26: =L25 -> 37854.989 | J26: =IF(H26>$B$17,0,I26*$B$16/12) -> 132.49246 | K26: =IF(H26>$B$17,0,MIN(I26,$B$18-J26)) -> 907.59614 | L26: =I26-K26 -> 36947.393
A27: Année 4 | B27: =SUMIFS($J:$J,$G:$G,4) -> 780.36712 | C27: =SUMIFS($K:$K,$G:$G,4) -> 11700.696 | D27: =IFERROR(INDEX($L:$L,MATCH(4*12,$H:$H,0)),0) -> 12201.697 | G27: =INT((H27-1)/12)+1 -> 2 | H27: 23 | I27: =L26 -> 36947.393 | J27: =IF(H27>$B$17,0,I27*$B$16/12) -> 129.31587 | K27: =IF(H27>$B$17,0,MIN(I27,$B$18-J27)) -> 910.77273 | L27: =I27-K27 -> 36036.62
A28: Année 5 | B28: =SUMIFS($J:$J,$G:$G,5) -> 279.36663 | C28: =SUMIFS($K:$K,$G:$G,5) -> 12201.697 | D28: =IFERROR(INDEX($L:$L,MATCH(5*12,$H:$H,0)),0) -> 0 | G28: =INT((H28-1)/12)+1 -> 2 | H28: 24 | I28: =L27 -> 36036.62 | J28: =IF(H28>$B$17,0,I28*$B$16/12) -> 126.12817 | K28: =IF(H28>$B$17,0,MIN(I28,$B$18-J28)) -> 913.96044 | L28: =I28-K28 -> 35122.659
G29: =INT((H29-1)/12)+1 -> 3 | H29: 25 | I29: =L28 -> 35122.659 | J29: =IF(H29>$B$17,0,I29*$B$16/12) -> 122.92931 | K29: =IF(H29>$B$17,0,MIN(I29,$B$18-J29)) -> 917.1593 | L29: =I29-K29 -> 34205.5
G30: =INT((H30-1)/12)+1 -> 3 | H30: 26 | I30: =L29 -> 34205.5 | J30: =IF(H30>$B$17,0,I30*$B$16/12) -> 119.71925 | K30: =IF(H30>$B$17,0,MIN(I30,$B$18-J30)) -> 920.36935 | L30: =I30-K30 -> 33285.131
G31: =INT((H31-1)/12)+1 -> 3 | H31: 27 | I31: =L30 -> 33285.131 | J31: =IF(H31>$B$17,0,I31*$B$16/12) -> 116.49796 | K31: =IF(H31>$B$17,0,MIN(I31,$B$18-J31)) -> 923.59065 | L31: =I31-K31 -> 32361.54
G32: =INT((H32-1)/12)+1 -> 3 | H32: 28 | I32: =L31 -> 32361.54 | J32: =IF(H32>$B$17,0,I32*$B$16/12) -> 113.26539 | K32: =IF(H32>$B$17,0,MIN(I32,$B$18-J32)) -> 926.82321 | L32: =I32-K32 -> 31434.717
G33: =INT((H33-1)/12)+1 -> 3 | H33: 29 | I33: =L32 -> 31434.717 | J33: =IF(H33>$B$17,0,I33*$B$16/12) -> 110.02151 | K33: =IF(H33>$B$17,0,MIN(I33,$B$18-J33)) -> 930.0671 | L33: =I33-K33 -> 30504.65
G34: =INT((H34-1)/12)+1 -> 3 | H34: 30 | I34: =L33 -> 30504.65 | J34: =IF(H34>$B$17,0,I34*$B$16/12) -> 106.76627 | K34: =IF(H34>$B$17,0,MIN(I34,$B$18-J34)) -> 933.32233 | L34: =I34-K34 -> 29571.328
G35: =INT((H35-1)/12)+1 -> 3 | H35: 31 | I35: =L34 -> 29571.328 | J35: =IF(H35>$B$17,0,I35*$B$16/12) -> 103.49965 | K35: =IF(H35>$B$17,0,MIN(I35,$B$18-J35)) -> 936.58896 | L35: =I35-K35 -> 28634.739
G36: =INT((H36-1)/12)+1 -> 3 | H36: 32 | I36: =L35 -> 28634.739 | J36: =IF(H36>$B$17,0,I36*$B$16/12) -> 100.22158 | K36: =IF(H36>$B$17,0,MIN(I36,$B$18-J36)) -> 939.86702 | L36: =I36-K36 -> 27694.872
G37: =INT((H37-1)/12)+1 -> 3 | H37: 33 | I37: =L36 -> 27694.872 | J37: =IF(H37>$B$17,0,I37*$B$16/12) -> 96.93205 | K37: =IF(H37>$B$17,0,MIN(I37,$B$18-J37)) -> 943.15655 | L37: =I37-K37 -> 26751.715
G38: =INT((H38-1)/12)+1 -> 3 | H38: 34 | I38: =L37 -> 26751.715 | J38: =IF(H38>$B$17,0,I38*$B$16/12) -> 93.631002 | K38: =IF(H38>$B$17,0,MIN(I38,$B$18-J38)) -> 946.4576 | L38: =I38-K38 -> 25805.257
G39: =INT((H39-1)/12)+1 -> 3 | H39: 35 | I39: =L38 -> 25805.257 | J39: =IF(H39>$B$17,0,I39*$B$16/12) -> 90.318401 | K39: =IF(H39>$B$17,0,MIN(I39,$B$18-J39)) -> 949.7702 | L39: =I39-K39 -> 24855.487
G40: =INT((H40-1)/12)+1 -> 3 | H40: 36 | I40: =L39 -> 24855.487 | J40: =IF(H40>$B$17,0,I40*$B$16/12) -> 86.994205 | K40: =IF(H40>$B$17,0,MIN(I40,$B$18-J40)) -> 953.0944 | L40: =I40-K40 -> 23902.393
... G64: =INT((H64-1)/12)+1 -> 5 | H64: 60 | I64: =L63 -> 1036.461 | J64: =IF(H64>$B$17,0,I64*$B$16/12) -> 3.6276135 | K64: =IF(H64>$B$17,0,MIN(I64,$B$18-J64)) -> 1036.461 | L64: =I64-K64 -> 0
...

Sheet Amortissements
A1: TABLEAU DES AMORTISSEMENTS (linéaire, acquisition au 1er mois)
A3: Immobilisation | B3: Valeur HT | C3: Durée (ans) | D3: Dotation A1 | E3: Dotation A2 | F3: Dotation A3 | G3: VNC fin A3
A4: Mini-pelle d'occasion | B4: =Hypothèses!$B$9 -> 27500 | C4: =Hypothèses!$B$17 -> 5 | D4: =IF(C4>=1,B4/C4,0) -> 5500 | E4: =IF(C4>=2,B4/C4,0) -> 5500 | F4: =IF(C4>=3,B4/C4,0) -> 5500 | G4: =B4-SUM(D4:F4) -> 11000
A5: Remorque plateau | B5: =Hypothèses!$B$10 -> 8000 | C5: =Hypothèses!$B$18 -> 5 | D5: =IF(C5>=1,B5/C5,0) -> 1600 | E5: =IF(C5>=2,B5/C5,0) -> 1600 | F5: =IF(C5>=3,B5/C5,0) -> 1600 | G5: =B5-SUM(D5:F5) -> 3200
A6: Camion benne | B6: =Hypothèses!$B$11 -> 20000 | C6: =Hypothèses!$B$19 -> 5 | D6: =IF(C6>=1,B6/C6,0) -> 4000 | E6: =IF(C6>=2,B6/C6,0) -> 4000 | F6: =IF(C6>=3,B6/C6,0) -> 4000 | G6: =B6-SUM(D6:F6) -> 8000
A7: Matériel & équipements | B7: =Hypothèses!$B$12 -> 5000 | C7: =Hypothèses!$B$20 -> 3 | D7: =IF(C7>=1,B7/C7,0) -> 1666.6667 | E7: =IF(C7>=2,B7/C7,0) -> 1666.6667 | F7: =IF(C7>=3,B7/C7,0) -> 1666.6667 | G7: =B7-SUM(D7:F7) -> 0
A8: TOTAL | B8: =SUM(B4:B7) -> 60500 | D8: =SUM(D4:D7) -> 12766.667 | E8: =SUM(E4:E7) -> 12766.667 | F8: =SUM(F4:F7) -> 12766.667 | G8: =SUM(G4:G7) -> 22200

Sheet Activité A1
A1: ACTIVITÉ MENSUELLE — ANNÉE 1
A2: Saisir en bleu le nombre de jours loués par mois (la saisonnalité TP est plus faible en hiver et en août).
A4: Mois | B4: =EDATE(Hypothèses!$B$5,0) -> 46388 | C4: =EDATE(Hypothèses!$B$5,1) -> 46419 | D4: =EDATE(Hypothèses!$B$5,2) -> 46447 | E4: =EDATE(Hypothèses!$B$5,3) -> 46478 | F4: =EDATE(Hypothèses!$B$5,4) -> 46508 | G4: =EDATE(Hypothèses!$B$5,5) -> 46539 | H4: =EDATE(Hypothèses!$B$5,6) -> 46569 | I4: =EDATE(Hypothèses!$B$5,7) -> 46600 | J4: =EDATE(Hypothèses!$B$5,8) -> 46631 | K4: =EDATE(Hypothèses!$B$5,9) -> 46661 | L4: =EDATE(Hypothèses!$B$5,10) -> 46692 | M4: =EDATE(Hypothèses!$B$5,11) -> 46722 | N4: Total A1
A5: Jours de location SANS opérateur | B5: 4 | C5: 5 | D5: 7 | E5: 9 | F5: 10 | G5: 10 | H5: 9 | I5: 6 | J5: 10 | K5: 10 | L5: 7 | M5: 5 | N5: =SUM(B5:M5) -> 92
A6: Jours de location AVEC opérateur | B6: 2 | C6: 3 | D6: 4 | E6: 5 | F6: 6 | G6: 6 | H6: 5 | I6: 3 | J6: 6 | K6: 6 | L6: 4 | M6: 3 | N6: =SUM(B6:M6) -> 53
A7: Total jours de location de la mini-pelle | B7: =B5+B6 -> 6 | C7: =C5+C6 -> 8 | D7: =D5+D6 -> 11 | E7: =E5+E6 -> 14 | F7: =F5+F6 -> 16 | G7: =G5+G6 -> 16 | H7: =H5+H6 -> 14 | I7: =I5+I6 -> 9 | ... M7: =M5+M6 -> 8 | N7: =SUM(B7:M7) -> 145
A8: Taux d'utilisation (jours loués / jours ouvrés) | B8: =IF(Hypothèses!$B$6=0,0,B7/Hypothèses!$B$6) -> 0.28571429 | C8: =IF(Hypothèses!$B$6=0,0,C7/Hypothèses!$B$6) -> 0.38095238 | D8: =IF(Hypothèses!$B$6=0,0,D7/Hypothèses!$B$6) -> 0.52380952 | E8: =IF(Hypothèses!$B$6=0,0,E7/Hypothèses!$B$6) -> 0.66666667 | F8: =IF(Hypothèses!$B$6=0,0,F7/Hypothèses!$B$6) -> 0.76190476 | G8: =IF(Hypothèses!$B$6=0,0,G7/Hypothèses!$B$6) -> 0.76190476 | H8: =IF(Hypothèses!$B$6=0,0,H7/Hypothèses!$B$6) -> 0.66666667 | I8: =IF(Hypothèses!$B$6=0,0,I7/Hypothèses!$B$6) -> 0.42857143 | ... M8: =IF(Hypothèses!$B$6=0,0,M7/Hypothèses!$B$6) -> 0.38095238 | N8: =IF(Hypothèses!$B$6=0,0,N7/(12*Hypothèses!$B$6)) -> 0.57539683
A10: CA location sans opérateur | B10: =B5*Hypothèses!$B$31 -> 1120 | C10: =C5*Hypothèses!$B$31 -> 1400 | D10: =D5*Hypothèses!$B$31 -> 1960 | E10: =E5*Hypothèses!$B$31 -> 2520 | F10: =F5*Hypothèses!$B$31 -> 2800 | G10: =G5*Hypothèses!$B$31 -> 2800 | H10: =H5*Hypothèses!$B$31 -> 2520 | I10: =I5*Hypothèses!$B$31 -> 1680 | ... M10: =M5*Hypothèses!$B$31 -> 1400 | N10: =SUM(B10:M10) -> 25760
A11: CA location avec opérateur | B11: =B6*Hypothèses!$B$32 -> 1500 | C11: =C6*Hypothèses!$B$32 -> 2250 | D11: =D6*Hypothèses!$B$32 -> 3000 | E11: =E6*Hypothèses!$B$32 -> 3750 | F11: =F6*Hypothèses!$B$32 -> 4500 | G11: =G6*Hypothèses!$B$32 -> 4500 | H11: =H6*Hypothèses!$B$32 -> 3750 | I11: =I6*Hypothèses!$B$32 -> 2250 | ... M11: =M6*Hypothèses!$B$32 -> 2250 | N11: =SUM(B11:M11) -> 39750
A12: CA LOCATION | B12: =B10+B11 -> 2620 | C12: =C10+C11 -> 3650 | D12: =D10+D11 -> 4960 | E12: =E10+E11 -> 6270 | F12: =F10+F11 -> 7300 | G12: =G10+G11 -> 7300 | H12: =H10+H11 -> 6270 | I12: =I10+I11 -> 3930 | ... M12: =M10+M11 -> 3650 | N12: =SUM(B12:M12) -> 65510
A14: Saisonnalité des travaux annexes (% du CA annuel) | B14: 0.04 | C14: 0.05 | D14: 0.08 | E14: 0.1 | F14: 0.1 | G14: 0.1 | H14: 0.09 | I14: 0.05 | J14: 0.11 | K14: 0.11 | L14: 0.09 | M14: 0.08 | N14: =SUM(B14:M14) -> 1 | O14: =IF(ROUND(N14,4)=1,"OK","≠ 100 % !") -> OK
A15: CA TRAVAUX ANNEXES | B15: =B14*Hypothèses!$B$33 -> 2600 | C15: =C14*Hypothèses!$B$33 -> 3250 | D15: =D14*Hypothèses!$B$33 -> 5200 | E15: =E14*Hypothèses!$B$33 -> 6500 | F15: =F14*Hypothèses!$B$33 -> 6500 | G15: =G14*Hypothèses!$B$33 -> 6500 | H15: =H14*Hypothèses!$B$33 -> 5850 | I15: =I14*Hypothèses!$B$33 -> 3250 | ... M15: =M14*Hypothèses!$B$33 -> 5200 | N15: =SUM(B15:M15) -> 65000
A17: CHIFFRE D'AFFAIRES TOTAL HT | B17: =B12+B15 -> 5220 | C17: =C12+C15 -> 6900 | D17: =D12+D15 -> 10160 | E17: =E12+E15 -> 12770 | F17: =F12+F15 -> 13800 | G17: =G12+G15 -> 13800 | H17: =H12+H15 -> 12120 | I17: =I12+I15 -> 7180 | ... M17: =M12+M15 -> 8850 | N17: =SUM(B17:M17) -> 130510
A19: Objectif location année 1 (donnée fournie) | N19: 65000
A20: Écart CA location / objectif | N20: =N12-N19 -> 510
A22: Point de vigilance : la mini-pelle sert aussi sur vos propres chantiers (travaux annexes). Les jours de chantier réduisent les jours disponibles à la location — surveiller le taux d'utilisation (ligne 8).

Sheet Compte de résultat
A1: COMPTE DE RÉSULTAT PRÉVISIONNEL (€ HT)
B3: Année 1 | C3: Année 2 | D3: Année 3 | E3: Commentaire
A4: PRODUITS
A5: CA location mini-pelle | B5: ='Activité A1'!$N$12 -> 65510 | C5: =B5*(1+Hypothèses!$B$34) -> 75336.5 | D5: =C5*(1+Hypothèses!$B$35) -> 82870.15 | E5: A1 = feuille Activité ; A2/A3 = croissance.
A6: CA travaux annexes | B6: ='Activité A1'!$N$15 -> 65000 | C6: =B6*(1+Hypothèses!$B$34) -> 74750 | D6: =C6*(1+Hypothèses!$B$35) -> 82225
A7: CHIFFRE D'AFFAIRES | B7: =B5+B6 -> 130510 | C7: =C5+C6 -> 150086.5 | D7: =D5+D6 -> 165095.15
A9: CHARGES VARIABLES
A10: Achats matériaux / fournitures (travaux) | B10: =B6*Hypothèses!$B$39 -> 19500 | C10: =C6*Hypothèses!$B$39 -> 22425 | D10: =D6*Hypothèses!$B$39 -> 24667.5
A11: Carburant & usure (location avec opérateur + travaux) | B11: ='Activité A1'!$N$6*Hypothèses!$B$40+B6*Hypothèses!$B$42 -> 5490 | C11: =B11*(1+Hypothèses!$B$34) -> 6313.5 | D11: =C11*(1+Hypothèses!$B$35) -> 6944.85
A12: Usure / entretien variable mini-pelle | B12: ='Activité A1'!$N$7*Hypothèses!$B$41 -> 1450 | C12: =B12*(1+Hypothèses!$B$34) -> 1667.5 | D12: =C12*(1+Hypothèses!$B$35) -> 1834.25
A13: Total charges variables | B13: =SUM(B10:B12) -> 26440 | C13: =SUM(C10:C12) -> 30406 | D13: =SUM(D10:D12) -> 33446.6
A14: MARGE SUR COÛTS VARIABLES | B14: =B7-B13 -> 104070 | C14: =C7-C13 -> 119680.5 | D14: =D7-D13 -> 131648.55
A15: Taux de marge sur coûts variables | B15: =IF(B7=0,0,B14/B7) -> 0.79741016 | C15: =IF(C7=0,0,C14/C7) -> 0.79741016 | D15: =IF(D7=0,0,D14/D7) -> 0.79741016
A17: CHARGES FIXES
A18: Charges externes fixes (assurances, comptable, entretien...) | B18: =Hypothèses!B$76 -> 17420 | C18: =Hypothèses!C$76 -> 17920 | D18: =Hypothèses!D$76 -> 18420 | E18: Détail dans la feuille Hypothèses.
A19: Frais d'établissement | B19: =Hypothèses!$B$13 -> 1200 | C19: 0 | D19: 0
A20: Rémunération nette des associés | B20: =Hypothèses!B$47*Hypothèses!$B$45*MAX(0,13-Hypothèses!$B$48) -> 18000 | C20: =Hypothèses!C$47*Hypothèses!$B$45*12 -> 36000 | D20: =Hypothèses!D$47*Hypothèses!$B$45*12 -> 48000 | E20: A1 : à partir du mois de début saisi dans les hypothèses.
A21: Cotisations sociales des dirigeants | B21: =B20*Hypothèses!$B$49 -> 8100 | C21: =C20*Hypothèses!$B$49 -> 16200 | D21: =D20*Hypothèses!$B$49 -> 21600
A22: EXCÉDENT BRUT D'EXPLOITATION (EBE) | B22: =B14-B18-B19-B20-B21 -> 59350 | C22: =C14-C18-C19-C20-C21 -> 49560.5 | D22: =D14-D18-D19-D20-D21 -> 43628.55
A23: Dotations aux amortissements | B23: =Amortissements!$D$8 -> 12766.667 | C23: =Amortissements!$E$8 -> 12766.667 | D23: =Amortissements!$F$8 -> 12766.667
A24: RÉSULTAT D'EXPLOITATION | B24: =B22-B23 -> 46583.333 | C24: =C22-C23 -> 36793.833 | D24: =D22-D23 -> 30861.883
A25: Charges financières (intérêts + frais de dossier en A1) | B25: =Financement!$B$24+Hypothèses!$B$27 -> 2663.2863 | C25: =Financement!$B$25 -> 1721.4997 | D25: =Financement!$B$26 -> 1260.7966
A26: RÉSULTAT AVANT IMPÔT | B26: =B24-B25 -> 43920.047 | C26: =C24-C25 -> 35072.334 | D26: =D24-D25 -> 29601.087
A27: Base imposable à l'IS (après report des déficits) | B27: =MAX(0,B26) -> 43920.047 | C27: =MAX(0,C26-B29) -> 35072.334 | D27: =MAX(0,D26-C29) -> 29601.087
A28: Impôt sur les sociétés | B28: =MIN(B27,Hypothèses!$B$54)*Hypothèses!$B$53+MAX(0,B27-Hypothèses!$B$54)*Hypothèses!$B$55 -> 6730.0118 | C28: =MIN(C27,Hypothèses!$B$54)*Hypothèses!$B$53+MAX(0,C27-Hypothèses!$B$54)*Hypothèses!$B$55 -> 5260.8501 | D28: =MIN(D27,Hypothèses!$B$54)*Hypothèses!$B$53+MAX(0,D27-Hypothèses!$B$54)*Hypothèses!$B$55 -> 4440.163
A29: Déficit reportable en fin d'année | B29: =MAX(0,-B26) -> 0 | C29: =MAX(0,B29-C26) -> 0 | D29: =MAX(0,C29-D26) -> 0 | E29: Info : déficits imputés sur les bénéfices suivants.
A30: RÉSULTAT NET | B30: =B26-B28 -> 37190.035 | C30: =C26-C28 -> 29811.484 | D30: =D26-D28 -> 25160.924
A31: Résultat net / CA | B31: =IF(B7=0,0,B30/B7) -> 0.28495928 | C31: =IF(C7=0,0,C30/C7) -> 0.19862868 | D31: =IF(D7=0,0,D30/D7) -> 0.15240256
A33: CAPACITÉ D'AUTOFINANCEMENT
A34: CAF (résultat net + amortissements) | B34: =B30+B23 -> 49956.702 | C34: =C30+C23 -> 42578.15 | D34: =D30+D23 -> 37927.59
A35: Remboursement du capital de l'emprunt | B35: =Financement!$C$24 -> 10317.777 | C35: =Financement!$C$25 -> 10759.564 | D35: =Financement!$C$26 -> 11220.267
A36: Trésorerie dégagée après remboursement | B36: =B34-B35 -> 39638.925 | C36: =C34-C35 -> 31818.587 | D36: =D34-D35 -> 26707.324 | E36: Doit rester positive : c'est ce que la banque regarde en premier.
A37: Couverture des annuités (CAF / capital remboursé) | B37: =IF(B35=0,0,B34/B35) -> 4.8418087 | C37: =IF(C35=0,0,C34/C35) -> 3.9572377 | D37: =IF(D35=0,0,D34/D35) -> 3.3802753

Sheet Trésorerie A1
A1: PLAN DE TRÉSORERIE MENSUEL — ANNÉE 1 (montants TTC)
A2: Hypothèses : investissements et apports au mois 1 ; location payée comptant ; travaux encaissés à 30 jours (mois suivant) ; TVA sur les encaissements (prestations de services), déclarée mensuellement et payée le mois suivant ; TVA des investissements préfinancée par un crédit relais, soldé au remboursement du crédit de TVA ; IS de l'année 1 payé en année 2.
A4: Mois | B4: ='Activité A1'!B4 -> 46388 | C4: ='Activité A1'!C4 -> 46419 | D4: ='Activité A1'!D4 -> 46447 | E4: ='Activité A1'!E4 -> 46478 | F4: ='Activité A1'!F4 -> 46508 | G4: ='Activité A1'!G4 -> 46539 | H4: ='Activité A1'!H4 -> 46569 | I4: ='Activité A1'!I4 -> 46600 | ... M4: ='Activité A1'!M4 -> 46722 | N4: Total A1
A5: ENCAISSEMENTS
A6: Apport en capital | B6: =Hypothèses!$B$23 -> 1000 | C6: 0 | D6: 0 | E6: 0 | F6: 0 | G6: 0 | H6: 0 | I6: 0 | J6: 0 | K6: 0 | L6: 0 | M6: 0 | N6: =SUM(B6:M6) -> 1000
A7: Apports en compte courant d'associés | B7: =Hypothèses!$B$24 -> 10000 | C7: 0 | D7: 0 | E7: 0 | F7: 0 | G7: 0 | H7: 0 | I7: 0 | J7: 0 | K7: 0 | L7: 0 | M7: 0 | N7: =SUM(B7:M7) -> 10000
A8: Déblocage de l'emprunt + crédit relais TVA | B8: =Financement!$E$6+Hypothèses!$B$57*Financement!$B$12 -> 68300 | C8: 0 | D8: 0 | E8: 0 | F8: 0 | G8: 0 | H8: 0 | I8: 0 | J8: 0 | K8: 0 | L8: 0 | M8: 0 | N8: =SUM(B8:M8) -> 68300
A9: Encaissements location (TTC) | B9: ='Activité A1'!B12*(1+Hypothèses!$B$52) -> 3144 | C9: ='Activité A1'!C12*(1+Hypothèses!$B$52) -> 4380 | D9: ='Activité A1'!D12*(1+Hypothèses!$B$52) -> 5952 | E9: ='Activité A1'!E12*(1+Hypothèses!$B$52) -> 7524 | F9: ='Activité A1'!F12*(1+Hypothèses!$B$52) -> 8760 | G9: ='Activité A1'!G12*(1+Hypothèses!$B$52) -> 8760 | H9: ='Activité A1'!H12*(1+Hypothèses!$B$52) -> 7524 | I9: ='Activité A1'!I12*(1+Hypothèses!$B$52) -> 4716 | ... M9: ='Activité A1'!M12*(1+Hypothèses!$B$52) -> 4380 | N9: =SUM(B9:M9) -> 78612
A10: Encaissements travaux (TTC, à 30 jours) | B10: 0 | C10: ='Activité A1'!B15*(1+Hypothèses!$B$52) -> 3120 | D10: ='Activité A1'!C15*(1+Hypothèses!$B$52) -> 3900 | E10: ='Activité A1'!D15*(1+Hypothèses!$B$52) -> 6240 | F10: ='Activité A1'!E15*(1+Hypothèses!$B$52) -> 7800 | G10: ='Activité A1'!F15*(1+Hypothèses!$B$52) -> 7800 | H10: ='Activité A1'!G15*(1+Hypothèses!$B$52) -> 7800 | I10: ='Activité A1'!H15*(1+Hypothèses!$B$52) -> 7020 | J10: ='Activité A1'!I15*(1+Hypothèses!$B$52) -> 3900 | ... M10: ='Activité A1'!L15*(1+Hypothèses!$B$52) -> 7020 | N10: =SUM(B10:M10) -> 71760
A11: TOTAL ENCAISSEMENTS | B11: =SUM(B6:B10) -> 82444 | C11: =SUM(C6:C10) -> 7500 | D11: =SUM(D6:D10) -> 9852 | E11: =SUM(E6:E10) -> 13764 | F11: =SUM(F6:F10) -> 16560 | G11: =SUM(G6:G10) -> 16560 | H11: =SUM(H6:H10) -> 15324 | I11: =SUM(I6:I10) -> 11736 | ... M11: =SUM(M6:M10) -> 11400 | N11: =SUM(B11:M11) -> 229672
A13: DÉCAISSEMENTS
A14: Investissements (TTC) | B14: =(Hypothèses!$B$9+Hypothèses!$B$10+Hypothèses!$B$11+Hypothèses!$B$12)*(1+Hypothèses!$B$52) -> 72600 | C14: 0 | D14: 0 | E14: 0 | F14: 0 | G14: 0 | H14: 0 | I14: 0 | J14: 0 | K14: 0 | L14: 0 | M14: 0 | N14: =SUM(B14:M14) -> 72600
A15: Frais d'établissement + frais de dossier | B15: =Hypothèses!$B$13+Hypothèses!$B$27 -> 1700 | C15: 0 | D15: 0 | E15: 0 | F15: 0 | G15: 0 | H15: 0 | I15: 0 | J15: 0 | K15: 0 | L15: 0 | M15: 0 | N15: =SUM(B15:M15) -> 1700
A16: Achats matériaux travaux (TTC) | B16: ='Activité A1'!B15*Hypothèses!$B$39*(1+Hypothèses!$B$52) -> 936 | C16: ='Activité A1'!C15*Hypothèses!$B$39*(1+Hypothèses!$B$52) -> 1170 | D16: ='Activité A1'!D15*Hypothèses!$B$39*(1+Hypothèses!$B$52) -> 1872 | E16: ='Activité A1'!E15*Hypothèses!$B$39*(1+Hypothèses!$B$52) -> 2340 | F16: ='Activité A1'!F15*Hypothèses!$B$39*(1+Hypothèses!$B$52) -> 2340 | G16: ='Activité A1'!G15*Hypothèses!$B$39*(1+Hypothèses!$B$52) -> 2340 | H16: ='Activité A1'!H15*Hypothèses!$B$39*(1+Hypothèses!$B$52) -> 2106 | I16: ='Activité A1'!I15*Hypothèses!$B$39*(1+Hypothèses!$B$52) -> 1170 | ... M16: ='Activité A1'!M15*Hypothèses!$B$39*(1+Hypothèses!$B$52) -> 1872 | N16: =SUM(B16:M16) -> 23400
A17: Carburant & usure (TTC) | B17: =('Activité A1'!B6*Hypothèses!$B$40+'Activité A1'!B15*Hypothèses!$B$42+'Activité A1'!B7*Hypothèses!$B$41)*(1+Hypothèses!$B$52) -> 331.2 | C17: =('Activité A1'!C6*Hypothèses!$B$40+'Activité A1'!C15*Hypothèses!$B$42+'Activité A1'!C7*Hypothèses!$B$41)*(1+Hypothèses!$B$52) -> 438 | D17: =('Activité A1'!D6*Hypothèses!$B$40+'Activité A1'!D15*Hypothèses!$B$42+'Activité A1'!D7*Hypothèses!$B$41)*(1+Hypothèses!$B$52) -> 650.4 | E17: =('Activité A1'!E6*Hypothèses!$B$40+'Activité A1'!E15*Hypothèses!$B$42+'Activité A1'!E7*Hypothèses!$B$41)*(1+Hypothèses!$B$52) -> 816 | F17: =('Activité A1'!F6*Hypothèses!$B$40+'Activité A1'!F15*Hypothèses!$B$42+'Activité A1'!F7*Hypothèses!$B$41)*(1+Hypothèses!$B$52) -> 876 | G17: =('Activité A1'!G6*Hypothèses!$B$40+'Activité A1'!G15*Hypothèses!$B$42+'Activité A1'!G7*Hypothèses!$B$41)*(1+Hypothèses!$B$52) -> 876 | H17: =('Activité A1'!H6*Hypothèses!$B$40+'Activité A1'!H15*Hypothèses!$B$42+'Activité A1'!H7*Hypothèses!$B$41)*(1+Hypothèses!$B$52) -> 769.2 | I17: =('Activité A1'!I6*Hypothèses!$B$40+'Activité A1'!I15*Hypothèses!$B$42+'Activité A1'!I7*Hypothèses!$B$41)*(1+Hypothèses!$B$52) -> 450 | ... M17: =('Activité A1'!M6*Hypothèses!$B$40+'Activité A1'!M15*Hypothèses!$B$42+'Activité A1'!M7*Hypothèses!$B$41)*(1+Hypothèses!$B$52) -> 578.4 | N17: =SUM(B17:M17) -> 8328
A18: Charges fixes externes (TTC, lissées sur 12 mois) | B18: =SUMPRODUCT(Hypothèses!$B$61:$B$75,1+Hypothèses!$E$61:$E$75*Hypothèses!$B$52)/12 -> 1637 | C18: =SUMPRODUCT(Hypothèses!$B$61:$B$75,1+Hypothèses!$E$61:$E$75*Hypothèses!$B$52)/12 -> 1637 | D18: =SUMPRODUCT(Hypothèses!$B$61:$B$75,1+Hypothèses!$E$61:$E$75*Hypothèses!$B$52)/12 -> 1637 | E18: =SUMPRODUCT(Hypothèses!$B$61:$B$75,1+Hypothèses!$E$61:$E$75*Hypothèses!$B$52)/12 -> 1637 | F18: =SUMPRODUCT(Hypothèses!$B$61:$B$75,1+Hypothèses!$E$61:$E$75*Hypothèses!$B$52)/12 -> 1637 | G18: =SUMPRODUCT(Hypothèses!$B$61:$B$75,1+Hypothèses!$E$61:$E$75*Hypothèses!$B$52)/12 -> 1637 | H18: =SUMPRODUCT(Hypothèses!$B$61:$B$75,1+Hypothèses!$E$61:$E$75*Hypothèses!$B$52)/12 -> 1637 | I18: =SUMPRODUCT(Hypothèses!$B$61:$B$75,1+Hypothèses!$E$61:$E$75*Hypothèses!$B$52)/12 -> 1637 | ... M18: =SUMPRODUCT(Hypothèses!$B$61:$B$75,1+Hypothèses!$E$61:$E$75*Hypothèses!$B$52)/12 -> 1637 | N18: =SUM(B18:M18) -> 19644
A19: Rémunérations nettes des associés | B19: =IF(1>=Hypothèses!$B$48,Hypothèses!$B$47*Hypothèses!$B$45,0) -> 0 | C19: =IF(2>=Hypothèses!$B$48,Hypothèses!$B$47*Hypothèses!$B$45,0) -> 0 | D19: =IF(3>=Hypothèses!$B$48,Hypothèses!$B$47*Hypothèses!$B$45,0) -> 0 | E19: =IF(4>=Hypothèses!$B$48,Hypothèses!$B$47*Hypothèses!$B$45,0) -> 2000 | F19: =IF(5>=Hypothèses!$B$48,Hypothèses!$B$47*Hypothèses!$B$45,0) -> 2000 | G19: =IF(6>=Hypothèses!$B$48,Hypothèses!$B$47*Hypothèses!$B$45,0) -> 2000 | H19: =IF(7>=Hypothèses!$B$48,Hypothèses!$B$47*Hypothèses!$B$45,0) -> 2000 | I19: =IF(8>=Hypothèses!$B$48,Hypothèses!$B$47*Hypothèses!$B$45,0) -> 2000 | J19: =IF(9>=Hypothèses!$B$48,Hypothèses!$B$47*Hypothèses!$B$45,0) -> 2000 | K19: =IF(10>=Hypothèses!$B$48,Hypothèses!$B$47*Hypothèses!$B$45,0) -> 2000 | L19: =IF(11>=Hypothèses!$B$48,Hypothèses!$B$47*Hypothèses!$B$45,0) -> 2000 | M19: =IF(12>=Hypothèses!$B$48,Hypothèses!$B$47*Hypothèses!$B$45,0) -> 2000 | N19: =SUM(B19:M19) -> 18000
A20: Cotisations sociales des dirigeants | B20: =B19*Hypothèses!$B$49 -> 0 | C20: =C19*Hypothèses!$B$49 -> 0 | D20: =D19*Hypothèses!$B$49 -> 0 | E20: =E19*Hypothèses!$B$49 -> 900 | F20: =F19*Hypothèses!$B$49 -> 900 | G20: =G19*Hypothèses!$B$49 -> 900 | H20: =H19*Hypothèses!$B$49 -> 900 | I20: =I19*Hypothèses!$B$49 -> 900 | ... M20: =M19*Hypothèses!$B$49 -> 900 | N20: =SUM(B20:M20) -> 8100
A21: Mensualité d'emprunt (+ remboursement du relais TVA) | B21: =Financement!$J$5+Financement!$K$5+IF(1=MAX(1,Hypothèses!$B$56),Hypothèses!$B$57*Financement!$B$12,0) -> 1040.0886 | C21: =Financement!$J$6+Financement!$K$6+IF(2=MAX(1,Hypothèses!$B$56),Hypothèses!$B$57*Financement!$B$12,0) -> 1040.0886 | D21: =Financement!$J$7+Financement!$K$7+IF(3=MAX(1,Hypothèses!$B$56),Hypothèses!$B$57*Financement!$B$12,0) -> 13140.089 | E21: =Financement!$J$8+Financement!$K$8+IF(4=MAX(1,Hypothèses!$B$56),Hypothèses!$B$57*Financement!$B$12,0) -> 1040.0886 | F21: =Financement!$J$9+Financement!$K$9+IF(5=MAX(1,Hypothèses!$B$56),Hypothèses!$B$57*Financement!$B$12,0) -> 1040.0886 | G21: =Financement!$J$10+Financement!$K$10+IF(6=MAX(1,Hypothèses!$B$56),Hypothèses!$B$57*Financement!$B$12,0) -> 1040.0886 | H21: =Financement!$J$11+Financement!$K$11+IF(7=MAX(1,Hypothèses!$B$56),Hypothèses!$B$57*Financement!$B$12,0) -> 1040.0886 | I21: =Financement!$J$12+Financement!$K$12+IF(8=MAX(1,Hypothèses!$B$56),Hypothèses!$B$57*Financement!$B$12,0) -> 1040.0886 | J21: =Financement!$J$13+Financement!$K$13+IF(9=MAX(1,Hypothèses!$B$56),Hypothèses!$B$57*Financement!$B$12,0) -> 1040.0886 | K21: =Financement!$J$14+Financement!$K$14+IF(10=MAX(1,Hypothèses!$B$56),Hypothèses!$B$57*Financement!$B$12,0) -> 1040.0886 | L21: =Financement!$J$15+Financement!$K$15+IF(11=MAX(1,Hypothèses!$B$56),Hypothèses!$B$57*Financement!$B$12,0) -> 1040.0886 | M21: =Financement!$J$16+Financement!$K$16+IF(12=MAX(1,Hypothèses!$B$56),Hypothèses!$B$57*Financement!$B$12,0) -> 1040.0886 | N21: =SUM(B21:M21) -> 24581.063
A22: TVA reversée (+) / remboursement du crédit de TVA (−) | B22: 0 | C22: =B31-IF(2=Hypothèses!$B$56,B32,0) -> 0 | D22: =C31-IF(3=Hypothèses!$B$56,C32,0) -> -11175.867 | E22: =D31-IF(4=Hypothèses!$B$56,D32,0) -> 1036.2667 | F22: =E31-IF(5=Hypothèses!$B$56,E32,0) -> 1582.6667 | G22: =F31-IF(6=Hypothèses!$B$56,F32,0) -> 2038.6667 | H22: =G31-IF(7=Hypothèses!$B$56,G32,0) -> 2038.6667 | I22: =H31-IF(8=Hypothèses!$B$56,H32,0) -> 1889.4667 | J22: =I31-IF(9=Hypothèses!$B$56,I32,0) -> 1500.6667 | K22: =J31-IF(10=Hypothèses!$B$56,J32,0) -> 1341.8667 | L22: =K31-IF(11=Hypothèses!$B$56,K32,0) -> 2121.8667 | M22: =L31-IF(12=Hypothèses!$B$56,L32,0) -> 1769.4667 | N22: =SUM(B22:M22) -> 4143.7333
A23: TOTAL DÉCAISSEMENTS | B23: =SUM(B14:B22) -> 78244.289 | C23: =SUM(C14:C22) -> 4285.0886 | D23: =SUM(D14:D22) -> 6123.6219 | E23: =SUM(E14:E22) -> 9769.3553 | F23: =SUM(F14:F22) -> 10375.755 | G23: =SUM(G14:G22) -> 10831.755 | H23: =SUM(H14:H22) -> 10490.955 | I23: =SUM(I14:I22) -> 9086.5553 | ... M23: =SUM(M14:M22) -> 9796.9553 | N23: =SUM(B23:M23) -> 180496.8
A25: SOLDE DU MOIS | B25: =B11-B23 -> 4199.7114 | C25: =C11-C23 -> 3214.9114 | D25: =D11-D23 -> 3728.3781 | E25: =E11-E23 -> 3994.6447 | F25: =F11-F23 -> 6184.2447 | G25: =G11-G23 -> 5728.2447 | H25: =H11-H23 -> 4833.0447 | I25: =I11-I23 -> 2649.4447 | ... M25: =M11-M23 -> 1603.0447 | N25: =SUM(B25:M25) -> 49175.203
A26: TRÉSORERIE FIN DE MOIS | B26: =B25 -> 4199.7114 | C26: =B26+C25 -> 7414.6228 | D26: =C26+D25 -> 11143.001 | E26: =D26+E25 -> 15137.646 | F26: =E26+F25 -> 21321.89 | G26: =F26+G25 -> 27050.135 | H26: =G26+H25 -> 31883.18 | I26: =H26+I25 -> 34532.624 | J26: =I26+J25 -> 36618.069 | ... M26: =L26+M25 -> 49175.203 | N26: =M26 -> 49175.203
A28: CALCUL DE LA TVA
A29: TVA collectée (sur encaissements) | B29: =(B9+B10)/(1+Hypothèses!$B$52)*Hypothèses!$B$52 -> 524 | C29: =(C9+C10)/(1+Hypothèses!$B$52)*Hypothèses!$B$52 -> 1250 | D29: =(D9+D10)/(1+Hypothèses!$B$52)*Hypothèses!$B$52 -> 1642 | E29: =(E9+E10)/(1+Hypothèses!$B$52)*Hypothèses!$B$52 -> 2294 | F29: =(F9+F10)/(1+Hypothèses!$B$52)*Hypothèses!$B$52 -> 2760 | G29: =(G9+G10)/(1+Hypothèses!$B$52)*Hypothèses!$B$52 -> 2760 | H29: =(H9+H10)/(1+Hypothèses!$B$52)*Hypothèses!$B$52 -> 2554 | I29: =(I9+I10)/(1+Hypothèses!$B$52)*Hypothèses!$B$52 -> 1956 | ... M29: =(M9+M10)/(1+Hypothèses!$B$52)*Hypothèses!$B$52 -> 1900 | N29: =SUM(B29:M29) -> 25062
A30: TVA déductible | B30: =(B14+B16+B17)/(1+Hypothèses!$B$52)*Hypothèses!$B$52+SUMPRODUCT(Hypothèses!$B$61:$B$75,Hypothèses!$E$61:$E$75)*Hypothèses!$B$52/12 -> 12496.533 | C30: =(C14+C16+C17)/(1+Hypothèses!$B$52)*Hypothèses!$B$52+SUMPRODUCT(Hypothèses!$B$61:$B$75,Hypothèses!$E$61:$E$75)*Hypothèses!$B$52/12 -> 453.33333 | D30: =(D14+D16+D17)/(1+Hypothèses!$B$52)*Hypothèses!$B$52+SUMPRODUCT(Hypothèses!$B$61:$B$75,Hypothèses!$E$61:$E$75)*Hypothèses!$B$52/12 -> 605.73333 | E30: =(E14+E16+E17)/(1+Hypothèses!$B$52)*Hypothèses!$B$52+SUMPRODUCT(Hypothèses!$B$61:$B$75,Hypothèses!$E$61:$E$75)*Hypothèses!$B$52/12 -> 711.33333 | F30: =(F14+F16+F17)/(1+Hypothèses!$B$52)*Hypothèses!$B$52+SUMPRODUCT(Hypothèses!$B$61:$B$75,Hypothèses!$E$61:$E$75)*Hypothèses!$B$52/12 -> 721.33333 | G30: =(G14+G16+G17)/(1+Hypothèses!$B$52)*Hypothèses!$B$52+SUMPRODUCT(Hypothèses!$B$61:$B$75,Hypothèses!$E$61:$E$75)*Hypothèses!$B$52/12 -> 721.33333 | H30: =(H14+H16+H17)/(1+Hypothèses!$B$52)*Hypothèses!$B$52+SUMPRODUCT(Hypothèses!$B$61:$B$75,Hypothèses!$E$61:$E$75)*Hypothèses!$B$52/12 -> 664.53333 | I30: =(I14+I16+I17)/(1+Hypothèses!$B$52)*Hypothèses!$B$52+SUMPRODUCT(Hypothèses!$B$61:$B$75,Hypothèses!$E$61:$E$75)*Hypothèses!$B$52/12 -> 455.33333 | ... M30: =(M14+M16+M17)/(1+Hypothèses!$B$52)*Hypothèses!$B$52+SUMPRODUCT(Hypothèses!$B$61:$B$75,Hypothèses!$E$61:$E$75)*Hypothèses!$B$52/12 -> 593.73333 | N30: =SUM(B30:M30) -> 19612
A31: TVA à payer (versée le mois suivant) | B31: =MAX(0,B29-B30-0) -> 0 | C31: =MAX(0,C29-C30-(B32-IF(2=Hypothèses!$B$56,B32,0))) -> 0 | D31: =MAX(0,D29-D30-(C32-IF(3=Hypothèses!$B$56,C32,0))) -> 1036.2667 | E31: =MAX(0,E29-E30-(D32-IF(4=Hypothèses!$B$56,D32,0))) -> 1582.6667 | F31: =MAX(0,F29-F30-(E32-IF(5=Hypothèses!$B$56,E32,0))) -> 2038.6667 | G31: =MAX(0,G29-G30-(F32-IF(6=Hypothèses!$B$56,F32,0))) -> 2038.6667 | H31: =MAX(0,H29-H30-(G32-IF(7=Hypothèses!$B$56,G32,0))) -> 1889.4667 | I31: =MAX(0,I29-I30-(H32-IF(8=Hypothèses!$B$56,H32,0))) -> 1500.6667 | J31: =MAX(0,J29-J30-(I32-IF(9=Hypothèses!$B$56,I32,0))) -> 1341.8667 | K31: =MAX(0,K29-K30-(J32-IF(10=Hypothèses!$B$56,J32,0))) -> 2121.8667 | L31: =MAX(0,L29-L30-(K32-IF(11=Hypothèses!$B$56,K32,0))) -> 1769.4667 | M31: =MAX(0,M29-M30-(L32-IF(12=Hypothèses!$B$56,L32,0))) -> 1306.2667 | N31: =SUM(B31:M31) -> 16625.867
A32: Crédit de TVA reporté en fin de mois | B32: =MAX(0,0-(B29-B30)) -> 11972.533 | C32: =MAX(0,(B32-IF(2=Hypothèses!$B$56,B32,0))-(C29-C30)) -> 11175.867 | D32: =MAX(0,(C32-IF(3=Hypothèses!$B$56,C32,0))-(D29-D30)) -> 0 | E32: =MAX(0,(D32-IF(4=Hypothèses!$B$56,D32,0))-(E29-E30)) -> 0 | F32: =MAX(0,(E32-IF(5=Hypothèses!$B$56,E32,0))-(F29-F30)) -> 0 | G32: =MAX(0,(F32-IF(6=Hypothèses!$B$56,F32,0))-(G29-G30)) -> 0 | H32: =MAX(0,(G32-IF(7=Hypothèses!$B$56,G32,0))-(H29-H30)) -> 0 | I32: =MAX(0,(H32-IF(8=Hypothèses!$B$56,H32,0))-(I29-I30)) -> 0 | J32: =MAX(0,(I32-IF(9=Hypothèses!$B$56,I32,0))-(J29-J30)) -> 0 | K32: =MAX(0,(J32-IF(10=Hypothèses!$B$56,J32,0))-(K29-K30)) -> 0 | L32: =MAX(0,(K32-IF(11=Hypothèses!$B$56,K32,0))-(L29-L30)) -> 0 | M32: =MAX(0,(L32-IF(12=Hypothèses!$B$56,L32,0))-(M29-M30)) -> 0
A34: Trésorerie minimale sur l'année 1 | N34: =MIN(B26:M26) -> 4199.7114
A35: TVA de décembre restant à payer en janvier A2 / crédit de TVA restant (remboursable sur demande) | N35: =M31-M32 -> 1306.2667
A36: Astuce : le crédit de TVA lié aux investissements peut faire l'objet d'une demande de remboursement auprès des impôts (formulaire 3519) pour soulager la trésorerie.

Sheet Rentabilité & seuil
A1: RENTABILITÉ DE LA MINI-PELLE & SEUIL DE RENTABILITÉ (année 1)
A2: Répond à la question : combien de jours de location par mois faut-il pour rentabiliser les achats ?
A4: Coût annuel de possession de la mini-pelle | B4: € / an | D4: Commentaire
A5: Amortissement de la mini-pelle | B5: =Amortissements!$D$4 -> 5500 | D5: Feuille Amortissements.
A6: Intérêts d'emprunt (quote-part mini-pelle) | B6: =IF(Financement!$B$11=0,0,Financement!$B$24*Hypothèses!$B$9/Financement!$B$11) -> 885.27341 | D6: Au prorata du prix de la pelle dans les besoins.
A7: Assurance mini-pelle | B7: =Hypothèses!$B$62 -> 1200
A8: VGP / contrôles | B8: =Hypothèses!$B$65 -> 400
A9: Entretien forfaitaire (50 % du forfait annuel) | B9: =Hypothèses!$B$64*0.5 -> 1250 | D9: Hypothèse : la moitié du forfait entretien concerne la pelle.
A10: Coût total de possession de la mini-pelle / an | B10: =SUM(B5:B9) -> 9235.2734
A11: Soit par mois | B11: =B10/12 -> 769.60612
A13: Marge dégagée par jour de location | B13: Sans opérateur | C13: Avec opérateur
A14: Prix de vente HT / jour | B14: =Hypothèses!$B$31 -> 280 | C14: =Hypothèses!$B$32 -> 750
A15: − Carburant | B15: 0 | C15: =Hypothèses!$B$40 -> 30 | D15: En location sèche, le carburant est à la charge du client.
A16: − Usure / entretien variable | B16: =Hypothèses!$B$41 -> 10 | C16: =Hypothèses!$B$41 -> 10
A17: − Temps de l'opérateur | D17: Non déduit ici : l'opérateur est un associé, sa rémunération est une charge fixe.
A18: Marge sur coût variable par jour | B18: =B14-B15-B16 -> 270 | C18: =C14-C15-C16 -> 710
A20: Nombre de jours de location nécessaires PAR MOIS pour couvrir… | B20: Sans opérateur | C20: Avec opérateur
A21: …le seul coût de possession de la mini-pelle | B21: =IF(B$18<=0,0,$B$11/B$18) -> 2.850393 | C21: =IF(C$18<=0,0,$B$11/C$18) -> 1.0839523 | D21: Ce que la pelle doit rapporter pour « se payer » elle-même.
A22: …la mensualité totale de l'emprunt + assurances/entretien pelle | B22: =IF(B$18<=0,0,(Financement!$B$18+($B$7+$B$8+$B$9)/12)/B$18) -> 4.7318096 | C22: =IF(C$18<=0,0,(Financement!$B$18+($B$7+$B$8+$B$9)/12)/C$18) -> 1.7994206 | D22: Vision trésorerie : la location rembourse tout le crédit (pelle + camion + remorque).
A23: …toutes les charges fixes de la société (hors rémunérations) | B23: =IF(B$18<=0,0,(('Compte de résultat'!$B$18+'Compte de résultat'!$B$19+'Compte de résultat'!$B$23+'Compte de résultat'!$B$25)/12)/B$18) -> 10.509245 | C23: =IF(C$18<=0,0,(('Compte de résultat'!$B$18+'Compte de résultat'!$B$19+'Compte de résultat'!$B$23+'Compte de résultat'!$B$25)/12)/C$18) -> 3.9964734 | D23: Hypothèse extrême : aucun CA travaux, la location porte toute la structure.
A24: …toutes les charges fixes, rémunérations des associés comprises | B24: =IF(B$18<=0,0,(('Compte de résultat'!$B$18+'Compte de résultat'!$B$19+'Compte de résultat'!$B$23+'Compte de résultat'!$B$25+'Compte de résultat'!$B$20+'Compte de résultat'!$B$21)/12)/B$18) -> 18.5648 | C24: =IF(C$18<=0,0,(('Compte de résultat'!$B$18+'Compte de résultat'!$B$19+'Compte de résultat'!$B$23+'Compte de résultat'!$B$25+'Compte de résultat'!$B$20+'Compte de résultat'!$B$21)/12)/C$18) -> 7.0598536 | D24: Idem, en payant les associés selon les hypothèses de l'année 1.
A25: Pour comparaison : jours loués prévus en moyenne par mois (feuille Activité) | B25: ='Activité A1'!$N$5/12 -> 7.6666667 | C25: ='Activité A1'!$N$6/12 -> 4.4166667
A26: Jours de location / mois pour atteindre 65 000 € de CA location avec un seul type de location | B26: =IF(Hypothèses!$B$31=0,0,'Activité A1'!$N$19/12/Hypothèses!$B$31) -> 19.345238 | C26: =IF(Hypothèses!$B$32=0,0,'Activité A1'!$N$19/12/Hypothèses!$B$32) -> 7.2222222
A28: Seuil de rentabilité global (année 1) | B28: Montant
A29: Charges fixes totales (externes, frais d'établissement, rémunérations, cotisations, amortissements, intérêts) | B29: ='Compte de résultat'!$B$18+'Compte de résultat'!$B$19+'Compte de résultat'!$B$20+'Compte de résultat'!$B$21+'Compte de résultat'!$B$23+'Compte de résultat'!$B$25 -> 60149.953
A30: Taux de marge sur coûts variables | B30: ='Compte de résultat'!$B$15 -> 0.79741016
A31: SEUIL DE RENTABILITÉ (CA HT minimum pour résultat = 0) | B31: =IF(B30<=0,0,B29/B30) -> 75431.636
A32: CA prévisionnel année 1 | B32: ='Compte de résultat'!$B$7 -> 130510
A33: Marge de sécurité (CA prévu − seuil) / CA prévu | B33: =IF(B32=0,0,(B32-B31)/B32) -> 0.42202409
A34: Point mort : mois où le seuil est atteint (CA supposé régulier) | B34: =IF(B32=0,0,B31/B32*12) -> 6.9357109
A36: Sensibilité : résultat avant impôt A1 selon le niveau d'activité | B36: % du CA prévu | C36: Résultat avant IS
A37: Scénario 60 % | B37: 0.6 | C37: =B37*'Compte de résultat'!$B$14-$B$29 -> 2292.047
A38: Scénario 70 % | B38: 0.7 | C38: =B38*'Compte de résultat'!$B$14-$B$29 -> 12699.047
A39: Scénario 80 % | B39: 0.8 | C39: =B39*'Compte de résultat'!$B$14-$B$29 -> 23106.047
A40: Scénario 90 % | B40: 0.9 | C40: =B40*'Compte de résultat'!$B$14-$B$29 -> 33513.047
A41: Scénario 100 % (prévisionnel) | B41: 1 | C41: =B41*'Compte de résultat'!$B$14-$B$29 -> 43920.047
A42: Scénario 110 % | B42: 1.1 | C42: =B42*'Compte de résultat'!$B$14-$B$29 -> 54327.047
A43: Scénario 120 % | B43: 1.2 | C43: =B43*'Compte de résultat'!$B$14-$B$29 -> 64734.047
A44: Hypothèse simplifiée : charges variables proportionnelles au CA, charges fixes inchangées.
